[2025-10-29T14:40:05.367+0000] {local_task_job_runner.py:120} INFO - ::group::Pre task execution logs
[2025-10-29T14:40:05.406+0000] {taskinstance.py:2076} INFO - Dependencies all met for dep_context=non-requeueable deps ti=<TaskInstance: flood_prediction_pipeline.predict_and_log scheduled__2025-10-29T14:35:00+00:00 [queued]>
[2025-10-29T14:40:05.423+0000] {taskinstance.py:2076} INFO - Dependencies all met for dep_context=requeueable deps ti=<TaskInstance: flood_prediction_pipeline.predict_and_log scheduled__2025-10-29T14:35:00+00:00 [queued]>
[2025-10-29T14:40:05.424+0000] {taskinstance.py:2306} INFO - Starting attempt 1 of 2
[2025-10-29T14:40:05.441+0000] {taskinstance.py:2330} INFO - Executing <Task(PythonOperator): predict_and_log> on 2025-10-29 14:35:00+00:00
[2025-10-29T14:40:05.452+0000] {standard_task_runner.py:90} INFO - Running: ['***', 'tasks', 'run', 'flood_prediction_pipeline', 'predict_and_log', 'scheduled__2025-10-29T14:35:00+00:00', '--job-id', '401', '--raw', '--subdir', 'DAGS_FOLDER/flood_prediction_dag.py', '--cfg-path', '/tmp/tmplch1648q']
[2025-10-29T14:40:05.454+0000] {standard_task_runner.py:91} INFO - Job 401: Subtask predict_and_log
[2025-10-29T14:40:05.454+0000] {logging_mixin.py:188} WARNING - /home/***/.local/lib/python3.12/site-packages/***/task/task_runner/standard_task_runner.py:61 DeprecationWarning: This process (pid=1526) is multi-threaded, use of fork() may lead to deadlocks in the child.
[2025-10-29T14:40:05.457+0000] {standard_task_runner.py:63} INFO - Started process 1534 to run task
[2025-10-29T14:40:05.620+0000] {task_command.py:426} INFO - Running <TaskInstance: flood_prediction_pipeline.predict_and_log scheduled__2025-10-29T14:35:00+00:00 [running]> on host 31e670d1ab03
[2025-10-29T14:40:05.767+0000] {taskinstance.py:2648} INFO - Exporting env vars: AIRFLOW_CTX_DAG_OWNER='***' AIRFLOW_CTX_DAG_ID='flood_prediction_pipeline' AIRFLOW_CTX_TASK_ID='predict_and_log' AIRFLOW_CTX_EXECUTION_DATE='2025-10-29T14:35:00+00:00' AIRFLOW_CTX_TRY_NUMBER='1' AIRFLOW_CTX_DAG_RUN_ID='scheduled__2025-10-29T14:35:00+00:00'
[2025-10-29T14:40:05.770+0000] {taskinstance.py:430} INFO - ::endgroup::
[2025-10-29T14:40:07.262+0000] {logging_mixin.py:188} WARNING - /home/***/.local/lib/python3.12/site-packages/sklearn/ensemble/_base.py:168 UserWarning: Loky-backed parallel loops cannot be called in a multiprocessing, setting n_jobs=1
[2025-10-29T14:40:07.276+0000] {logging_mixin.py:188} WARNING - /home/***/.local/lib/python3.12/site-packages/sklearn/ensemble/_base.py:168 UserWarning: Loky-backed parallel loops cannot be called in a multiprocessing, setting n_jobs=1
[2025-10-29T14:40:07.284+0000] {logging_mixin.py:188} WARNING - /home/***/.local/lib/python3.12/site-packages/sklearn/ensemble/_base.py:168 UserWarning: Loky-backed parallel loops cannot be called in a multiprocessing, setting n_jobs=1
[2025-10-29T14:40:07.291+0000] {logging_mixin.py:188} WARNING - /home/***/.local/lib/python3.12/site-packages/sklearn/ensemble/_base.py:168 UserWarning: Loky-backed parallel loops cannot be called in a multiprocessing, setting n_jobs=1
[2025-10-29T14:40:07.299+0000] {logging_mixin.py:188} WARNING - /home/***/.local/lib/python3.12/site-packages/sklearn/ensemble/_base.py:168 UserWarning: Loky-backed parallel loops cannot be called in a multiprocessing, setting n_jobs=1
[2025-10-29T14:40:07.306+0000] {logging_mixin.py:188} WARNING - /home/***/.local/lib/python3.12/site-packages/sklearn/ensemble/_base.py:168 UserWarning: Loky-backed parallel loops cannot be called in a multiprocessing, setting n_jobs=1
[2025-10-29T14:40:07.340+0000] {logging_mixin.py:188} INFO - ‚ùå Prediction failed: Error tokenizing data. C error: Expected 8 fields in line 102, saw 21
[2025-10-29T14:40:07.345+0000] {logging_mixin.py:188} WARNING - Traceback (most recent call last):
[2025-10-29T14:40:07.346+0000] {logging_mixin.py:188} WARNING -   File "/opt/***/dags/flood_prediction_dag.py", line 209, in predict_and_log
    full_log = pd.read_csv(PRED_LOG_PATH)
               ^^^^^^^^^^^^^^^^^^^^^^^^^^
[2025-10-29T14:40:07.346+0000] {logging_mixin.py:188} WARNING -   File "/home/***/.local/lib/python3.12/site-packages/pandas/io/parsers/readers.py", line 948, in read_csv
    return _read(filepath_or_buffer, kwds)
           ^^^^^^^^^^^^^^^^^^^^^^^^^^^^^^^
[2025-10-29T14:40:07.347+0000] {logging_mixin.py:188} WARNING -   File "/home/***/.local/lib/python3.12/site-packages/pandas/io/parsers/readers.py", line 617, in _read
    return parser.read(nrows)
           ^^^^^^^^^^^^^^^^^^
[2025-10-29T14:40:07.348+0000] {logging_mixin.py:188} WARNING -   File "/home/***/.local/lib/python3.12/site-packages/pandas/io/parsers/readers.py", line 1748, in read
    ) = self._engine.read(  # type: ignore[attr-defined]
        ^^^^^^^^^^^^^^^^^^^^^^^^^^^^^^^^^^^^^^^^^^^^^^^^
[2025-10-29T14:40:07.348+0000] {logging_mixin.py:188} WARNING -   File "/home/***/.local/lib/python3.12/site-packages/pandas/io/parsers/c_parser_wrapper.py", line 234, in read
    chunks = self._reader.read_low_memory(nrows)
             ^^^^^^^^^^^^^^^^^^^^^^^^^^^^^^^^^^^
[2025-10-29T14:40:07.349+0000] {logging_mixin.py:188} WARNING -   File "parsers.pyx", line 843, in pandas._libs.parsers.TextReader.read_low_memory
[2025-10-29T14:40:07.349+0000] {logging_mixin.py:188} WARNING -   File "parsers.pyx", line 904, in pandas._libs.parsers.TextReader._read_rows
[2025-10-29T14:40:07.349+0000] {logging_mixin.py:188} WARNING -   File "parsers.pyx", line 879, in pandas._libs.parsers.TextReader._tokenize_rows
[2025-10-29T14:40:07.350+0000] {logging_mixin.py:188} WARNING -   File "parsers.pyx", line 890, in pandas._libs.parsers.TextReader._check_tokenize_status
[2025-10-29T14:40:07.350+0000] {logging_mixin.py:188} WARNING -   File "parsers.pyx", line 2058, in pandas._libs.parsers.raise_parser_error
[2025-10-29T14:40:07.351+0000] {logging_mixin.py:188} WARNING - pandas.errors.ParserError: Error tokenizing data. C error: Expected 8 fields in line 102, saw 21
[2025-10-29T14:40:07.375+0000] {python.py:237} INFO - Done. Returned value was: Prediction_Failed
[2025-10-29T14:40:07.376+0000] {taskinstance.py:441} INFO - ::group::Post task execution logs
[2025-10-29T14:40:07.395+0000] {taskinstance.py:1206} INFO - Marking task as SUCCESS. dag_id=flood_prediction_pipeline, task_id=predict_and_log, run_id=scheduled__2025-10-29T14:35:00+00:00, execution_date=20251029T143500, start_date=20251029T144005, end_date=20251029T144007
[2025-10-29T14:40:07.483+0000] {local_task_job_runner.py:240} INFO - Task exited with return code 0
[2025-10-29T14:40:07.515+0000] {taskinstance.py:3498} INFO - 1 downstream tasks scheduled from follow-on schedule check
[2025-10-29T14:40:07.520+0000] {local_task_job_runner.py:222} INFO - ::endgroup::
