[2025-10-19T09:35:04.734+0000] {local_task_job_runner.py:120} INFO - ::group::Pre task execution logs
[2025-10-19T09:35:04.765+0000] {taskinstance.py:2076} INFO - Dependencies all met for dep_context=non-requeueable deps ti=<TaskInstance: flood_prediction_pipeline.predict_and_log scheduled__2025-10-19T09:30:00+00:00 [queued]>
[2025-10-19T09:35:04.776+0000] {taskinstance.py:2076} INFO - Dependencies all met for dep_context=requeueable deps ti=<TaskInstance: flood_prediction_pipeline.predict_and_log scheduled__2025-10-19T09:30:00+00:00 [queued]>
[2025-10-19T09:35:04.778+0000] {taskinstance.py:2306} INFO - Starting attempt 1 of 2
[2025-10-19T09:35:04.801+0000] {taskinstance.py:2330} INFO - Executing <Task(PythonOperator): predict_and_log> on 2025-10-19 09:30:00+00:00
[2025-10-19T09:35:04.814+0000] {logging_mixin.py:188} WARNING - /home/***/.local/lib/python3.12/site-packages/***/task/task_runner/standard_task_runner.py:61 DeprecationWarning: This process (pid=332) is multi-threaded, use of fork() may lead to deadlocks in the child.
[2025-10-19T09:35:04.813+0000] {standard_task_runner.py:90} INFO - Running: ['***', 'tasks', 'run', 'flood_prediction_pipeline', 'predict_and_log', 'scheduled__2025-10-19T09:30:00+00:00', '--job-id', '332', '--raw', '--subdir', 'DAGS_FOLDER/flood_prediction_dag.py', '--cfg-path', '/tmp/tmp50jwix1g']
[2025-10-19T09:35:04.815+0000] {standard_task_runner.py:63} INFO - Started process 335 to run task
[2025-10-19T09:35:04.816+0000] {standard_task_runner.py:91} INFO - Job 332: Subtask predict_and_log
[2025-10-19T09:35:04.892+0000] {task_command.py:426} INFO - Running <TaskInstance: flood_prediction_pipeline.predict_and_log scheduled__2025-10-19T09:30:00+00:00 [running]> on host d59dd3e0b4a4
[2025-10-19T09:35:05.134+0000] {taskinstance.py:2648} INFO - Exporting env vars: AIRFLOW_CTX_DAG_OWNER='***' AIRFLOW_CTX_DAG_ID='flood_prediction_pipeline' AIRFLOW_CTX_TASK_ID='predict_and_log' AIRFLOW_CTX_EXECUTION_DATE='2025-10-19T09:30:00+00:00' AIRFLOW_CTX_TRY_NUMBER='1' AIRFLOW_CTX_DAG_RUN_ID='scheduled__2025-10-19T09:30:00+00:00'
[2025-10-19T09:35:05.139+0000] {taskinstance.py:430} INFO - ::endgroup::
[2025-10-19T09:35:06.459+0000] {logging_mixin.py:188} WARNING - /home/***/.local/lib/python3.12/site-packages/sklearn/ensemble/_base.py:168 UserWarning: Loky-backed parallel loops cannot be called in a multiprocessing, setting n_jobs=1
[2025-10-19T09:35:06.467+0000] {logging_mixin.py:188} WARNING - /home/***/.local/lib/python3.12/site-packages/sklearn/ensemble/_base.py:168 UserWarning: Loky-backed parallel loops cannot be called in a multiprocessing, setting n_jobs=1
[2025-10-19T09:35:06.558+0000] {logging_mixin.py:188} WARNING - 2025/10/19 09:35:06 WARNING mlflow.utils.git_utils: Failed to import Git (the Git executable is probably not on your PATH), so Git SHA is not available. Error: Failed to initialize: Bad git executable.
The git executable must be specified in one of the following ways:
    - be included in your $PATH
    - be set via $GIT_PYTHON_GIT_EXECUTABLE
    - explicitly set via git.refresh(<full-path-to-git-executable>)

All git commands will error until this is rectified.

This initial message can be silenced or aggravated in the future by setting the
$GIT_PYTHON_REFRESH environment variable. Use one of the following values:
    - quiet|q|silence|s|silent|none|n|0: for no message or exception
    - warn|w|warning|log|l|1: for a warning message (logging level CRITICAL, displayed by default)
    - error|e|exception|raise|r|2: for a raised exception

Example:
    export GIT_PYTHON_REFRESH=quiet
[2025-10-19T09:35:06.732+0000] {logging_mixin.py:188} WARNING - 2025/10/19 09:35:06 WARNING mlflow.models.model: `artifact_path` is deprecated. Please use `name` instead.
[2025-10-19T09:35:06.840+0000] {logging_mixin.py:188} INFO - üèÉ View run Live Flood Prediction at: http://mlflow:5000/#/experiments/1/runs/5e472a95261144d3a7655249419acaa7
[2025-10-19T09:35:06.841+0000] {logging_mixin.py:188} INFO - üß™ View experiment at: http://mlflow:5000/#/experiments/1
[2025-10-19T09:35:06.889+0000] {logging_mixin.py:188} INFO - ‚ùå Prediction failed: API request to endpoint /api/2.0/mlflow/logged-models failed with error code 404 != 200. Response body: '<!doctype html>
<html lang=en>
<title>404 Not Found</title>
<h1>Not Found</h1>
<p>The requested URL was not found on the server. If you entered the URL manually please check your spelling and try again.</p>
'
[2025-10-19T09:35:06.891+0000] {python.py:237} INFO - Done. Returned value was: {'error': "API request to endpoint /api/2.0/mlflow/logged-models failed with error code 404 != 200. Response body: '<!doctype html>\n<html lang=en>\n<title>404 Not Found</title>\n<h1>Not Found</h1>\n<p>The requested URL was not found on the server. If you entered the URL manually please check your spelling and try again.</p>\n'"}
[2025-10-19T09:35:06.892+0000] {taskinstance.py:441} INFO - ::group::Post task execution logs
[2025-10-19T09:35:06.923+0000] {taskinstance.py:1206} INFO - Marking task as SUCCESS. dag_id=flood_prediction_pipeline, task_id=predict_and_log, run_id=scheduled__2025-10-19T09:30:00+00:00, execution_date=20251019T093000, start_date=20251019T093504, end_date=20251019T093506
[2025-10-19T09:35:07.001+0000] {local_task_job_runner.py:240} INFO - Task exited with return code 0
[2025-10-19T09:35:07.028+0000] {taskinstance.py:3498} INFO - 0 downstream tasks scheduled from follow-on schedule check
[2025-10-19T09:35:07.034+0000] {local_task_job_runner.py:222} INFO - ::endgroup::
