[2025-10-29T20:10:06.393+0000] {local_task_job_runner.py:120} INFO - ::group::Pre task execution logs
[2025-10-29T20:10:06.415+0000] {taskinstance.py:2076} INFO - Dependencies all met for dep_context=non-requeueable deps ti=<TaskInstance: flood_prediction_pipeline.log_to_database scheduled__2025-10-29T20:05:00+00:00 [queued]>
[2025-10-29T20:10:06.424+0000] {taskinstance.py:2076} INFO - Dependencies all met for dep_context=requeueable deps ti=<TaskInstance: flood_prediction_pipeline.log_to_database scheduled__2025-10-29T20:05:00+00:00 [queued]>
[2025-10-29T20:10:06.425+0000] {taskinstance.py:2306} INFO - Starting attempt 1 of 2
[2025-10-29T20:10:06.442+0000] {taskinstance.py:2330} INFO - Executing <Task(PythonOperator): log_to_database> on 2025-10-29 20:05:00+00:00
[2025-10-29T20:10:06.452+0000] {standard_task_runner.py:90} INFO - Running: ['***', 'tasks', 'run', 'flood_prediction_pipeline', 'log_to_database', 'scheduled__2025-10-29T20:05:00+00:00', '--job-id', '264', '--raw', '--subdir', 'DAGS_FOLDER/flood_prediction_dag.py', '--cfg-path', '/tmp/tmpg9m8at97']
[2025-10-29T20:10:06.452+0000] {logging_mixin.py:188} WARNING - /home/***/.local/lib/python3.12/site-packages/***/task/task_runner/standard_task_runner.py:61 DeprecationWarning: This process (pid=23340) is multi-threaded, use of fork() may lead to deadlocks in the child.
[2025-10-29T20:10:06.454+0000] {standard_task_runner.py:91} INFO - Job 264: Subtask log_to_database
[2025-10-29T20:10:06.454+0000] {standard_task_runner.py:63} INFO - Started process 23348 to run task
[2025-10-29T20:10:06.502+0000] {task_command.py:426} INFO - Running <TaskInstance: flood_prediction_pipeline.log_to_database scheduled__2025-10-29T20:05:00+00:00 [running]> on host db3c1202c602
[2025-10-29T20:10:06.579+0000] {taskinstance.py:2648} INFO - Exporting env vars: AIRFLOW_CTX_DAG_OWNER='***' AIRFLOW_CTX_DAG_ID='flood_prediction_pipeline' AIRFLOW_CTX_TASK_ID='log_to_database' AIRFLOW_CTX_EXECUTION_DATE='2025-10-29T20:05:00+00:00' AIRFLOW_CTX_TRY_NUMBER='1' AIRFLOW_CTX_DAG_RUN_ID='scheduled__2025-10-29T20:05:00+00:00'
[2025-10-29T20:10:06.582+0000] {taskinstance.py:430} INFO - ::endgroup::
[2025-10-29T20:10:06.666+0000] {base.py:84} INFO - Using connection ID 'postgres_default' for task execution.
[2025-10-29T20:10:06.670+0000] {taskinstance.py:441} INFO - ::group::Post task execution logs
[2025-10-29T20:10:06.671+0000] {taskinstance.py:2905} ERROR - Task failed with exception
Traceback (most recent call last):
  File "/home/airflow/.local/lib/python3.12/site-packages/airflow/models/taskinstance.py", line 465, in _execute_task
    result = _execute_callable(context=context, **execute_callable_kwargs)
             ^^^^^^^^^^^^^^^^^^^^^^^^^^^^^^^^^^^^^^^^^^^^^^^^^^^^^^^^^^^^^
  File "/home/airflow/.local/lib/python3.12/site-packages/airflow/models/taskinstance.py", line 432, in _execute_callable
    return execute_callable(context=context, **execute_callable_kwargs)
           ^^^^^^^^^^^^^^^^^^^^^^^^^^^^^^^^^^^^^^^^^^^^^^^^^^^^^^^^^^^^
  File "/home/airflow/.local/lib/python3.12/site-packages/airflow/models/baseoperator.py", line 400, in wrapper
    return func(self, *args, **kwargs)
           ^^^^^^^^^^^^^^^^^^^^^^^^^^^
  File "/home/airflow/.local/lib/python3.12/site-packages/airflow/operators/python.py", line 235, in execute
    return_value = self.execute_callable()
                   ^^^^^^^^^^^^^^^^^^^^^^^
  File "/home/airflow/.local/lib/python3.12/site-packages/airflow/operators/python.py", line 252, in execute_callable
    return self.python_callable(*self.op_args, **self.op_kwargs)
           ^^^^^^^^^^^^^^^^^^^^^^^^^^^^^^^^^^^^^^^^^^^^^^^^^^^^^
  File "/opt/airflow/dags/flood_prediction_dag.py", line 255, in log_to_postgres
    pg_hook.run(create_table_sql)
  File "/home/airflow/.local/lib/python3.12/site-packages/airflow/providers/common/sql/hooks/sql.py", line 411, in run
    with closing(self.get_conn()) as conn:
                 ^^^^^^^^^^^^^^^
  File "/home/airflow/.local/lib/python3.12/site-packages/airflow/providers/postgres/hooks/postgres.py", line 161, in get_conn
    self.conn = psycopg2.connect(**conn_args)
                ^^^^^^^^^^^^^^^^^^^^^^^^^^^^^
  File "/home/airflow/.local/lib/python3.12/site-packages/psycopg2/__init__.py", line 122, in connect
    conn = _connect(dsn, connection_factory=connection_factory, **kwasync)
           ^^^^^^^^^^^^^^^^^^^^^^^^^^^^^^^^^^^^^^^^^^^^^^^^^^^^^^^^^^^^^^^
psycopg2.OperationalError: connection to server at "postgres" (172.18.0.2), port 5432 failed: FATAL:  password authentication failed for user "postgres"

[2025-10-29T20:10:06.685+0000] {taskinstance.py:1206} INFO - Marking task as UP_FOR_RETRY. dag_id=flood_prediction_pipeline, task_id=log_to_database, run_id=scheduled__2025-10-29T20:05:00+00:00, execution_date=20251029T200500, start_date=20251029T201006, end_date=20251029T201006
[2025-10-29T20:10:06.698+0000] {standard_task_runner.py:110} ERROR - Failed to execute job 264 for task log_to_database (connection to server at "postgres" (172.18.0.2), port 5432 failed: FATAL:  password authentication failed for user "postgres"
; 23348)
[2025-10-29T20:10:06.711+0000] {local_task_job_runner.py:240} INFO - Task exited with return code 1
[2025-10-29T20:10:06.728+0000] {taskinstance.py:3498} INFO - 0 downstream tasks scheduled from follow-on schedule check
[2025-10-29T20:10:06.734+0000] {local_task_job_runner.py:222} INFO - ::endgroup::
